Traceback (most recent call last):
  File "/dccstor/autofair/busekorkmaz/mmlu_pro/lib/python3.10/site-packages/huggingface_hub/utils/_errors.py", line 304, in hf_raise_for_status
    response.raise_for_status()
  File "/dccstor/autofair/busekorkmaz/mmlu_pro/lib/python3.10/site-packages/requests/models.py", line 1024, in raise_for_status
    raise HTTPError(http_error_msg, response=self)
requests.exceptions.HTTPError: 404 Client Error: Not Found for url: https://huggingface.co/None/resolve/main/config.json

The above exception was the direct cause of the following exception:

Traceback (most recent call last):
  File "/dccstor/autofair/busekorkmaz/mmlu_pro/lib/python3.10/site-packages/transformers/utils/hub.py", line 402, in cached_file
    resolved_file = hf_hub_download(
  File "/dccstor/autofair/busekorkmaz/mmlu_pro/lib/python3.10/site-packages/huggingface_hub/utils/_deprecation.py", line 101, in inner_f
    return f(*args, **kwargs)
  File "/dccstor/autofair/busekorkmaz/mmlu_pro/lib/python3.10/site-packages/huggingface_hub/utils/_validators.py", line 114, in _inner_fn
    return fn(*args, **kwargs)
  File "/dccstor/autofair/busekorkmaz/mmlu_pro/lib/python3.10/site-packages/huggingface_hub/file_download.py", line 1240, in hf_hub_download
    return _hf_hub_download_to_cache_dir(
  File "/dccstor/autofair/busekorkmaz/mmlu_pro/lib/python3.10/site-packages/huggingface_hub/file_download.py", line 1347, in _hf_hub_download_to_cache_dir
    _raise_on_head_call_error(head_call_error, force_download, local_files_only)
  File "/dccstor/autofair/busekorkmaz/mmlu_pro/lib/python3.10/site-packages/huggingface_hub/file_download.py", line 1854, in _raise_on_head_call_error
    raise head_call_error
  File "/dccstor/autofair/busekorkmaz/mmlu_pro/lib/python3.10/site-packages/huggingface_hub/file_download.py", line 1751, in _get_metadata_or_catch_error
    metadata = get_hf_file_metadata(
  File "/dccstor/autofair/busekorkmaz/mmlu_pro/lib/python3.10/site-packages/huggingface_hub/utils/_validators.py", line 114, in _inner_fn
    return fn(*args, **kwargs)
  File "/dccstor/autofair/busekorkmaz/mmlu_pro/lib/python3.10/site-packages/huggingface_hub/file_download.py", line 1673, in get_hf_file_metadata
    r = _request_wrapper(
  File "/dccstor/autofair/busekorkmaz/mmlu_pro/lib/python3.10/site-packages/huggingface_hub/file_download.py", line 376, in _request_wrapper
    response = _request_wrapper(
  File "/dccstor/autofair/busekorkmaz/mmlu_pro/lib/python3.10/site-packages/huggingface_hub/file_download.py", line 400, in _request_wrapper
    hf_raise_for_status(response)
  File "/dccstor/autofair/busekorkmaz/mmlu_pro/lib/python3.10/site-packages/huggingface_hub/utils/_errors.py", line 352, in hf_raise_for_status
    raise RepositoryNotFoundError(message, response) from e
huggingface_hub.utils._errors.RepositoryNotFoundError: 404 Client Error. (Request ID: Root=1-66eea5ef-7f0a589e1a6165474d866621;b8e94113-6471-4367-b581-313bf6cdfece)

Repository Not Found for url: https://huggingface.co/None/resolve/main/config.json.
Please make sure you specified the correct `repo_id` and `repo_type`.
If you are trying to access a private or gated repo, make sure you are authenticated.

The above exception was the direct cause of the following exception:

Traceback (most recent call last):
  File "/dccstor/autofair/busekorkmaz/factual-bias-mitigation/scripts/mmlu/evaluate_vllm.py", line 331, in <module>
    main()
  File "/dccstor/autofair/busekorkmaz/factual-bias-mitigation/scripts/mmlu/evaluate_vllm.py", line 245, in main
    model, tokenizer = load_model(model_name)
  File "/dccstor/autofair/busekorkmaz/factual-bias-mitigation/scripts/mmlu/evaluate_vllm.py", line 46, in load_model
    llm = LLM(model=model_name, gpu_memory_utilization=float(args.gpu_util),
  File "/dccstor/autofair/busekorkmaz/mmlu_pro/lib/python3.10/site-packages/vllm/entrypoints/llm.py", line 123, in __init__
    self.llm_engine = LLMEngine.from_engine_args(
  File "/dccstor/autofair/busekorkmaz/mmlu_pro/lib/python3.10/site-packages/vllm/engine/llm_engine.py", line 272, in from_engine_args
    engine_config = engine_args.create_engine_config()
  File "/dccstor/autofair/busekorkmaz/mmlu_pro/lib/python3.10/site-packages/vllm/engine/arg_utils.py", line 520, in create_engine_config
    model_config = ModelConfig(
  File "/dccstor/autofair/busekorkmaz/mmlu_pro/lib/python3.10/site-packages/vllm/config.py", line 121, in __init__
    self.hf_config = get_config(self.model, trust_remote_code, revision,
  File "/dccstor/autofair/busekorkmaz/mmlu_pro/lib/python3.10/site-packages/vllm/transformers_utils/config.py", line 23, in get_config
    config = AutoConfig.from_pretrained(
  File "/dccstor/autofair/busekorkmaz/mmlu_pro/lib/python3.10/site-packages/transformers/models/auto/configuration_auto.py", line 976, in from_pretrained
    config_dict, unused_kwargs = PretrainedConfig.get_config_dict(pretrained_model_name_or_path, **kwargs)
  File "/dccstor/autofair/busekorkmaz/mmlu_pro/lib/python3.10/site-packages/transformers/configuration_utils.py", line 632, in get_config_dict
    config_dict, kwargs = cls._get_config_dict(pretrained_model_name_or_path, **kwargs)
  File "/dccstor/autofair/busekorkmaz/mmlu_pro/lib/python3.10/site-packages/transformers/configuration_utils.py", line 689, in _get_config_dict
    resolved_config_file = cached_file(
  File "/dccstor/autofair/busekorkmaz/mmlu_pro/lib/python3.10/site-packages/transformers/utils/hub.py", line 425, in cached_file
    raise EnvironmentError(
OSError: None is not a local folder and is not a valid model identifier listed on 'https://huggingface.co/models'
If this is a private repository, make sure to pass a token having permission to this repo either by logging in with `huggingface-cli login` or by passing `token=<your_token>`
